Workbook

Sheet Summary
B1: TOUR BUDGET · SUMMARY
B2: All figures linked directly to individual sheets · Fill each tab → Summary updates automatically
B4: Artist name:
B5: Tour name:
B6: Currency:
B8: OPERATION | C8: PERIOD | D8: TOTAL COST | E8: TOTAL REVENUES | F8: MERCH MARGIN | G8: NET RESULT | H8: CUMULATIVE NET RESULT
B9: Pre-Production | C9: =IFERROR(IF(AND('Pre-Production'!C4<>"", 'Pre-Production'!C5<>""), TEXT('Pre-Production'!C4,"DD/MM/YY")&" → "&TEXT('Pre-Production'!C5,"DD/MM/YY"),""),"") | D9: ='Pre-Production'!E75 -> 0 | E9: ='Pre-Production'!E88 -> 0 | F9: 0 | G9: =-'Pre-Production'!E92 -> 0 | H9: =G9 -> 0
B10: Release Show | C10: =IFERROR(IF('Release Show'!C8<>"",TEXT('Release Show'!C8,"DD/MM/YY"),""),"") | D10: ='Release Show'!E66 -> 0 | E10: ='Release Show'!H28 -> 0 | F10: ='Release Show'!H57 -> 0 | G10: ='Release Show'!H59 -> 0 | H10: =H9+G10 -> 0
B11: Regional Tour | C11: =IFERROR(IF(AND('Regional Tour'!C9<>"",'Regional Tour'!C10<>""),TEXT('Regional Tour'!C9,"DD/MM/YY")&" → "&TEXT('Regional Tour'!C10,"DD/MM/YY"),""),"") | D11: ='Regional Tour'!D85 -> 0 | E11: ='Regional Tour'!E102 -> 0 | F11: ='Regional Tour'!E112 -> 0 | G11: ='Regional Tour'!E116 -> 0 | H11: =H10+G11 -> 0
B12: International Tour | C12: =IFERROR(IF(AND('International Tour'!C9<>"",'International Tour'!C10<>""),TEXT('International Tour'!C9,"DD/MM/YY")&" → "&TEXT('International Tour'!C10,"DD/MM/YY"),""),"") | D12: ='International Tour'!D85 -> 0 | E12: ='International Tour'!E102 -> 0 | F12: ='International Tour'!E112 -> 0 | G12: ='International Tour'!E116 -> 0 | H12: =H11+G12 -> 0
B13: Major Show | C13: =IFERROR(IF('Major Show'!C8<>"",TEXT('Major Show'!C8,"DD/MM/YY"),""),"") | D13: ='Major Show'!E69 -> 0 | E13: ='Major Show'!H28 -> 0 | F13: ='Major Show'!H57 -> 0 | G13: ='Major Show'!H59 -> 0 | H13: =H12+G13 -> 0
B15: TOTAL | D15: =SUM(D9:D13) -> 0 | E15: =SUM(E9:E13) -> 0 | F15: =SUM(F9:F13) -> 0 | G15: =SUM(G9:G13) -> 0 | H15: =H13 -> 0
B19: PROJECT TIMELINE
B21: PHASE | C21: START DATE | D21: END DATE | E21: DURATION (days) | F21: DURATION (months)
B22: Pre-Production | C22: ='Pre-Production'!C4 -> 0 | D22: ='Pre-Production'!C5 -> 0 | E22: ='Pre-Production'!C6 | F22: ='Pre-Production'!D6
B23: Release Show | C23: ='Release Show'!C8 -> 0 | D23: ='Release Show'!C8 -> 0
B24: Regional Tour | C24: ='Regional Tour'!C9 -> 0 | D24: ='Regional Tour'!C10 -> 0 | E24: ='Regional Tour'!C11 | F24: ='Regional Tour'!D11
B25: International Tour | C25: ='International Tour'!C9 -> 0 | D25: ='International Tour'!C10 -> 0 | E25: ='International Tour'!C11 | F25: ='International Tour'!D11
B26: Major Show | C26: ='Major Show'!C8 -> 0 | D26: ='Major Show'!C8 -> 0
B28: TOTAL PROJECT DURATION
B30: ★ Colour code: Blue = input · Black = formula · ★ = key assumption to define with group · All amounts in JOD (changeable)

Sheet Pre-Production
B1: PRE-PRODUCTION · REHEARSALS & CREATIVE RESIDENCY
B2: Artist: | C2: =Summary!C4 -> 0
B3: Tour name:
B4: Start date:
B5: End date:
B6: Duration: | C6: =IF(AND(C4<>"",C5<>""),C5-C4,"") | D6: =IF(AND(C4<>"",C5<>""),ROUND((C5-C4)/30,1),"")
B7: Nb Rehearsal Days:
B8: Nb Residency Days:
B10: ★ EMPLOYER SOCIAL CHARGES RATE (define with group)
B11: ★ FOREIGN ARTIST WITHHOLDING TAX RATE (define with group)
B12: ★ MANAGEMENT COMMISSION RATE (define with group)
B14: POSITION | C14: FEE / DAY | D14: NB DAYS | E14: TOTAL
B15: Artist Bill
B16: Singer | E16: =C16*D16 -> 0
B17: Keys | E17: =C17*D17 -> 0
B18: Drummer | E18: =C18*D18 -> 0
B19: Bass | E19: =C19*D19 -> 0
E20: =C20*D20 -> 0
E21: =C21*D21 -> 0
B22: Musician (foreign artist) | E22: =C22*D22 -> 0
B23: Subtotal gross fees | E23: =SUM(E16:E22) -> 0
B24: Employer social charges (★) — local musicians | E24: =E10*(E16+E17+E18+E19+E20) -> 0
B25: Withholding tax (★) — foreign artists | E25: =E11*(E21+E22) -> 0
B26: TOTAL ARTIST BILL PAYROLL | E26: =E23+E24+E25 -> 0
B28: Technical Crew
B29: General Stage Manager | E29: =C29*D29 -> 0
B30: Sound Engineer (FOH) | E30: =C30*D30 -> 0
B31: Lighting Designer | E31: =C31*D31 -> 0
B32: Backline Tech | E32: =C32*D32 -> 0
B33: Wardrobe / Styling | E33: =C33*D33 -> 0
B34: Roads / Crew | E34: =C34*D34 -> 0
B35: Runner | E35: =C35*D35 -> 0
B36: Subtotal gross fees | E36: =SUM(E29:E35) -> 0
B37: Employer social charges (★) | E37: =E10*E36 -> 0
B38: Withholding tax (★) — foreign tech (if any) | E38: =E11*0 -> 0
B39: TOTAL TECHNICAL CREW PAYROLL | E39: =E36+E37+E38 -> 0
B41: Creative & Technical Costs
B42: Studio / Rehearsal Room Rental | E42: =C42*D42 -> 0
B43: Residency Venue | E43: =C43*D43 -> 0
E44: =C44*D44 -> 0
...

Sheet Release Show
B1: RELEASE SHOW · SELF-PRODUCED DATE
B2: ★ EMPLOYER SOCIAL CHARGES RATE
B3: ★ FOREIGN ARTIST WITHHOLDING TAX
B4: ★ MANAGEMENT COMMISSION RATE
B5: ★ BOOKING AGENT COMMISSION RATE
B7: Artist: | C7: =Summary!C4 -> 0
B8: Date:
B9: Venue:
B10: City:
B11: Capacity (Jauge):
B13: EXPENSES | C13: UNIT COST | D13: QTY | E13: TOTAL HT | G13: TICKETING STRUCTURE
B14: Venue | G14: Capacity (Jauge)
B15: Venue rental (fixed fee) | E15: =C15*D15 -> 0 | G15: Invitations (comps)
B16: Venue rental (variable %) | E16: =C16*D16 -> 0 | G16: Venue servitudes
B17: Video recording / Broadcast | E17: =C17*D17 -> 0 | G17: Tickets to sell | H17: =H14-H15-H16 -> 0
B18: Overtime hours | E18: =C18*D18 -> 0
B19: Ticketing / box-office fees | E19: =C19*D19 -> 0 | G19: TICKET PRICES
G20: Early Bird price
B21: Security provision | E21: =C20*D20 -> 0 | G21: Presale price
B22: Subtotal Venue | E22: =SUM(E15:E20) -> 0 | G22: Door price — auto: presale × 1.25 | H22: =H21*1.25 -> 0
B24: Artist Bill (incl. payroll charges) | G24: TICKET SALES
G25: Early Bird tickets sold
G26: Early Bird revenue | H26: =H20*H25 -> 0
B27: Singer | E27: =C24*D24 -> 0 | G27: Presale tickets sold
B28: Keys | E28: =C25*D25 -> 0 | G28: Presale revenue | H28: =H21*H27 -> 0
B29: Bass Player | E29: =C26*D26 -> 0 | G29: Door tickets sold
B30: Drums | E30: =C27*D27 -> 0 | G30: Door revenue | H30: =H22*H29 -> 0
B31: Musician (foreign artist) | E31: =C28*D28 -> 0 | G31: GROSS TICKET REVENUE (TTC) | H31: =H26+H28+H30 -> 0
B32: Musician (foreign artist) | E32: =C29*D29 -> 0
B33: Subtotal gross fees (Artist Bill) | E33: =SUM(E24:E29) -> 0 | G33: TAXES & DEDUCTIONS (Jordan)
B34: Employer social charges (★) — local musicians | E34: =E2*(E24+E25+E26+E27) -> 0 | G34: GST / Sales Tax on tickets (~16% Jordan — to confirm) | H34: =0.16*H31 -> 0
B35: Withholding tax (★) — foreign artists | G35: Entertainment / ticketing tax (rate TBC)
B36: TOTAL ARTIST BILL PAYROLL | E36: =E30+E31+E32 -> 0 | G36: Other local levies
G37: TOTAL TAXES & DEDUCTIONS | H37: =SUM(H34:H36) -> 0
B38: Production Tech | G38: NET TICKET REVENUE | H38: =H28-H34 -> 0
B39: Sound system rental | E39: =C36*D36 -> 0
B40: Lighting rig rental | E40: =C37*D37 -> 0 | G40: OTHER REVENUES
B41: Video / LED wall | E41: =C38*D38 -> 0 | G41: Sponsorship / brand partnership
B42: Backline rental | E42: =C39*D39 -> 0
B43: Rigging / Stage | E43: =C40*D40 -> 0 | G43: TOTAL OTHER REVENUES | H43: =H38+H39 -> 0
...

Sheet Regional Tour
B1: SHOW COST (PLATEAU) · Regional Dates — Performance fee / Guarantee model
B2: ★ EMPLOYER SOCIAL CHARGES RATE
B3: ★ FOREIGN ARTIST WITHHOLDING TAX
B4: ★ MANAGEMENT COMMISSION RATE
B5: ★ BOOKING AGENT COMMISSION RATE
B7: Artist: | C7: =Summary!C4 -> 0
B8: Tour name:
B9: Start date:
B10: End date:
B11: Duration: | C11: =IF(AND(C9<>"",C10<>""),C10-C9,"") | D11: =IF(AND(C9<>"",C10<>""),ROUND((C10-C9)/30,1),"")
B12: Nb of Shows:
B14: POSITION | C14: FEE / SHOW | D14: GROSS × 16 SHOWS
B17: BLOC 1 · SHOW COST
B19: Lead Artist
B20: Lead Artist | D20: =C20*$C$12 -> 0
B21: Subtotal gross fees | D21: =SUM(D20:D20) -> 0
B22: Employer social charges (★) | D22: =E2*D21 -> 0
B23: Foreign artist withholding (★) | D23: =E3*D21 -> 0
B24: TOTAL LEAD ARTIST PAYROLL | D24: =D21+D22+D23 -> 0
B26: Band Members
B27: Singer | D27: =C27*$C$12 -> 0
B28: Keys | D28: =C28*$C$12 -> 0
B29: Drums | D29: =C29*$C$12 -> 0
B30: Bass | D30: =C30*$C$12 -> 0
D31: =C31*$C$12 -> 0
D32: =C32*$C$12 -> 0
B33: Subtotal gross fees | D33: =SUM(D27:D32) -> 0
B34: Employer social charges (★) — local musicians | D34: =E2*(D27+D28+D29+D30) -> 0
B35: Withholding tax (★) — foreign artists | D35: =E3*(D31+D32) -> 0
B36: TOTAL BAND MEMBERS PAYROLL | D36: =D33+D34+D35 -> 0
B38: Technical Crew
B39: General Stage Manager | D39: =C39*$C$12 -> 0
B40: Sound Engineer (FOH) | D40: =C40*$C$12 -> 0
B41: Lighting Designer | D41: =C41*$C$12 -> 0
B42: Backline Tech | D42: =C42*$C$12 -> 0
B43: Tour Manager | D43: =C43*$C$12 -> 0
B44: Roads / Crew | D44: =C44*$C$12 -> 0
B45: Subtotal gross fees | D45: =SUM(D39:D44) -> 0
B46: Employer social charges (★) | D46: =E2*D45 -> 0
B47: Foreign artist withholding (★) | D47: =E3*D45 -> 0
...

Sheet International Tour
B1: SHOW COST (PLATEAU) · International Dates — Performance fee / Guarantee model
B2: ★ EMPLOYER SOCIAL CHARGES RATE
B3: ★ FOREIGN ARTIST WITHHOLDING TAX
B4: ★ MANAGEMENT COMMISSION RATE
B5: ★ BOOKING AGENT COMMISSION RATE
B7: Artist: | C7: =Summary!C4 -> 0
B8: Tour name:
B9: Start date:
B10: End date:
B11: Duration: | C11: =IF(AND(C9<>"",C10<>""),C10-C9,"") | D11: =IF(AND(C9<>"",C10<>""),ROUND((C10-C9)/30,1),"")
B12: Nb of Shows:
B14: POSITION | C14: FEE / SHOW | D14: GROSS × 10 SHOWS
B17: BLOC 1 · SHOW COST
B19: Lead Artist
B20: Lead Artist | D20: =C20*$C$12 -> 0
B21: Subtotal gross fees | D21: =SUM(D20:D20) -> 0
B22: Employer social charges (★) | D22: =E2*D21 -> 0
B23: Foreign artist withholding (★) | D23: =E3*D21 -> 0
B24: TOTAL LEAD ARTIST PAYROLL | D24: =D21+D22+D23 -> 0
B26: Band Members
B27: Drummer | D27: =C27*$C$12 -> 0
B28: Bass Player | D28: =C28*$C$12 -> 0
B29: Keys | D29: =C29*$C$12 -> 0
B30: Oud / Guitar | D30: =C30*$C$12 -> 0
B31: Musician (foreign artist) | D31: =C31*$C$12 -> 0
B32: Musician (foreign artist) | D32: =C32*$C$12 -> 0
B33: Subtotal gross fees | D33: =SUM(D27:D32) -> 0
B34: Employer social charges (★) — local musicians | D34: =E2*(D27+D28+D29+D30) -> 0
B35: Withholding tax (★) — foreign artists | D35: =E3*(D31+D32) -> 0
B36: TOTAL BAND MEMBERS PAYROLL | D36: =D33+D34+D35 -> 0
B38: Technical Crew
B39: General Stage Manager | D39: =C39*$C$12 -> 0
B40: Sound Engineer (FOH) | D40: =C40*$C$12 -> 0
B41: Lighting Designer | D41: =C41*$C$12 -> 0
B42: Backline Tech | D42: =C42*$C$12 -> 0
B43: Tour Manager | D43: =C43*$C$12 -> 0
B44: Roads / Crew | D44: =C44*$C$12 -> 0
B45: Subtotal gross fees | D45: =SUM(D39:D44) -> 0
B46: Employer social charges (★) | D46: =E2*D45 -> 0
B47: Foreign artist withholding (★) | D47: =E3*D45 -> 0
...

Sheet Major Show
B1: MAJOR SHOW · SELF-PRODUCED DATE · LARGE VENUE
B2: ★ EMPLOYER SOCIAL CHARGES RATE
B3: ★ FOREIGN ARTIST WITHHOLDING TAX
B4: ★ MANAGEMENT COMMISSION RATE
B5: ★ BOOKING AGENT COMMISSION RATE
B7: Artist: | C7: =Summary!C4 -> 0
B8: Date:
B9: Venue:
B10: City:
B11: Capacity (Jauge):
B13: EXPENSES | C13: UNIT COST | D13: QTY | E13: TOTAL HT | G13: TICKETING STRUCTURE
B14: Venue | G14: Capacity (Jauge)
B15: Venue rental (fixed fee) | E15: =C15*D15 -> 0 | G15: Invitations (comps)
B16: Venue rental (variable %) | E16: =C16*D16 -> 0 | G16: Venue servitudes
B17: Video recording / Broadcast | E17: =C17*D17 -> 0 | G17: Tickets to sell | H17: =H14-H15-H16 -> 0
B18: Overtime hours | E18: =C18*D18 -> 0
B19: Ticketing / box-office fees | E19: =C19*D19 -> 0 | G19: TICKET PRICES
B20: Security provision | E20: =C20*D20 -> 0 | G20: Presale price
B21: Subtotal Venue | E21: =SUM(E15:E20) -> 0 | G21: Door price — auto: presale × 1.25 | H21: =H20*1.25 -> 0
B23: Artist Bill (incl. payroll charges) | G23: TICKET SALES
B24: Lead Artist | E24: =C24*D24 -> 0 | G24: Presale tickets sold
B25: Drummer | E25: =C25*D25 -> 0 | G25: Presale revenue | H25: =H20*H24 -> 0
B26: Bass Player | E26: =C26*D26 -> 0 | G26: Door tickets sold
B27: Keys | E27: =C27*D27 -> 0 | G27: Door revenue | H27: =H21*H26 -> 0
B28: Musician (foreign artist) | E28: =C28*D28 -> 0 | G28: GROSS TICKET REVENUE (TTC) | H28: =H25+H27 -> 0
B29: Musician (foreign artist) | E29: =C29*D29 -> 0
B30: Subtotal gross fees (Artist Bill) | E30: =SUM(E24:E29) -> 0 | G30: TAXES & DEDUCTIONS (Jordan)
B31: Employer social charges (★) — local musicians | E31: =E2*(E24+E25+E26+E27) -> 0 | G31: GST / Sales Tax on tickets (~16% Jordan — to confirm) | H31: =0.16*H28 -> 0
B32: Withholding tax (★) — foreign artists | E32: =E3*(E28+E29) -> 0 | G32: Entertainment / ticketing tax (rate TBC)
B33: TOTAL ARTIST BILL PAYROLL | E33: =E30+E31+E32 -> 0 | G33: Other local levies
G34: TOTAL TAXES & DEDUCTIONS | H34: =SUM(H31:H33) -> 0
B35: Production Tech | G35: NET TICKET REVENUE | H35: =H28-H34 -> 0
B36: Sound system rental | E36: =C36*D36 -> 0
B37: Lighting rig rental | E37: =C37*D37 -> 0 | G37: OTHER REVENUES
B38: Video / LED wall | E38: =C38*D38 -> 0 | G38: Crowdfunding
B39: Backline rental | E39: =C39*D39 -> 0 | G39: Sponsorship / brand partnership
B40: Rigging / Stage | E40: =C40*D40 -> 0 | G40: TOTAL OTHER REVENUES | H40: =H38+H39 -> 0
B41: Special effects | E41: =C41*D41 -> 0
B42: Miscellaneous | E42: =C42*D42 -> 0 | G42: COMMISSIONS
B43: Subtotal Production Tech | E43: =SUM(E36:E42) -> 0 | G43: Management commission (★) | H43: =E4*(H35+H40) -> 0
...
